<mujoco model="roki">
  <compiler angle="radian" autolimits="true" />
  <option timestep="0.005" cone="elliptic" tolerance="1e-08" integrator="implicit" iterations="100" />
  <default>
    <joint damping="0.41" armature="0.045" frictionloss="0.03"/>
    <default class="visual">
      <geom type="mesh" contype="0" conaffinity="0" group="2"/>
    </default>
    <default class="collision">
      <geom type="mesh" group="3"/>
    </default>
  </default>
  <asset>
    <texture type="2d" name="groundplane" builtin="gradient" rgb1="0.2 0.9 0.4" rgb2="0.1 0.0 0.1" height="10" width="10"/>
    <material name="groundplane" texture="groundplane" texrepeat="1 1" reflectance="0.2"/>
    <material name="Nylon_12_(with_Formlabs_Fuse_1_3D_Printer)" rgba="0.247059 0.247059 0.247059 1"/>
    <material name="Titanium_-_Polished" rgba="0.74902 0.729412 0.701961 1"/>
    <material name="Aluminum_-_Anodized_Glossy_(Grey)" rgba="0.27451 0.27451 0.27451 1"/>
    <material name="Steel_-_Satin" rgba="0.627451 0.627451 0.627451 1"/>
    <material name="PA_12_-_Nylon_-_PA_603-CF_(with_EOS_P_3D_Printers)" rgba="0.247059 0.247059 0.247059 1"/>
    <material name="Generic" rgba="0.098039 0.098039 0.098039 1"/>
    <material name="ABS_(White)" rgba="0.964706 0.964706 0.952941 1"/>
    <material name="Glass_(Clear)" rgba="0.964706 0.964706 0.952941 1"/>
    <material name="Opaque(76,76,76)" rgba="0.298039 0.298039 0.298039 1"/>
    <material name="Aluminum_-_Satin" rgba="0.960784 0.960784 0.964706 1"/>
    <material name="Opaque(192,255,255)" rgba="0.752941 1 1 1"/>
    <material name="Silver_-_Polished" rgba="0.984314 0.980392 0.960784 1"/>
    <material name="Opaque(255,0,0)" rgba="1 0 0 1"/>
    <material name="Opaque(0,0,255)" rgba="0 0 1 1"/>
    <material name="Rubber_-_Soft" rgba="0.152941 0.152941 0.152941 1"/>
    <material name="Opaque(0,128,0)" rgba="0 0.501961 0 1"/>
    <material name="Carbon_Fiber_-_Plain" rgba="0.098039 0.098039 0.098039 1"/>
    <material name="Aluminum_-_Bead_Blasted" rgba="0.960784 0.960784 0.964706 1"/>
    <material name="Plastic_-_Translucent_Glossy_(Red)" rgba="0.768627 0.207843 0.152941 1"/>
    <mesh name="arm_v2_1_mesh" file="roki/arm_v2_1_mesh.obj"/>
    <mesh name="arm_v2__1__1_mesh" file="roki/arm_v2__1__1_mesh.obj"/>
    <mesh name="elbow_1_mesh_0" file="roki/elbow_1_mesh_0.obj"/>
    <mesh name="elbow_1_mesh_1" file="roki/elbow_1_mesh_1.obj"/>
    <mesh name="elbow_1_mesh_2" file="roki/elbow_1_mesh_2.obj"/>
    <mesh name="elbow_1_mesh_3" file="roki/elbow_1_mesh_3.obj"/>
    <mesh name="elbow_1_mesh_4" file="roki/elbow_1_mesh_4.obj"/>
    <mesh name="elbow_u_1_mesh" file="roki/elbow_u_1_mesh.obj"/>
    <mesh name="elbow_u__1__1_mesh" file="roki/elbow_u__1__1_mesh.obj"/>
    <mesh name="elbow__1__1_mesh_0" file="roki/elbow__1__1_mesh_0.obj"/>
    <mesh name="elbow__1__1_mesh_1" file="roki/elbow__1__1_mesh_1.obj"/>
    <mesh name="elbow__1__1_mesh_2" file="roki/elbow__1__1_mesh_2.obj"/>
    <mesh name="elbow__1__1_mesh_3" file="roki/elbow__1__1_mesh_3.obj"/>
    <mesh name="elbow__1__1_mesh_4" file="roki/elbow__1__1_mesh_4.obj"/>
    <mesh name="head_1_mesh_0" file="roki/head_1_mesh_0.obj"/>
    <mesh name="head_1_mesh_1" file="roki/head_1_mesh_1.obj"/>
    <mesh name="head_1_mesh_2" file="roki/head_1_mesh_2.obj"/>
    <mesh name="head_1_mesh_3" file="roki/head_1_mesh_3.obj"/>
    <mesh name="head_1_mesh_4" file="roki/head_1_mesh_4.obj"/>
    <mesh name="head_1_mesh_5" file="roki/head_1_mesh_5.obj"/>
    <mesh name="head_1_mesh_6" file="roki/head_1_mesh_6.obj"/>
    <mesh name="head_1_mesh_7" file="roki/head_1_mesh_7.obj"/>
    <mesh name="head_1_mesh_8" file="roki/head_1_mesh_8.obj"/>
    <mesh name="head_1_mesh_9" file="roki/head_1_mesh_9.obj"/>
    <mesh name="head_1_mesh_10" file="roki/head_1_mesh_10.obj"/>
    <mesh name="head_1_mesh_11" file="roki/head_1_mesh_11.obj"/>
    <mesh name="hip_u_1_mesh" file="roki/hip_u_1_mesh.obj"/>
    <mesh name="hip_u_3_mesh" file="roki/hip_u_3_mesh.obj"/>
    <mesh name="hip__1__1_mesh_0" file="roki/hip__1__1_mesh_0.obj"/>
    <mesh name="hip__1__1_mesh_1" file="roki/hip__1__1_mesh_1.obj"/>
    <mesh name="hip__1__1_mesh_2" file="roki/hip__1__1_mesh_2.obj"/>
    <mesh name="hip__1__1_mesh_3" file="roki/hip__1__1_mesh_3.obj"/>
    <mesh name="hip__1__1_mesh_4" file="roki/hip__1__1_mesh_4.obj"/>
    <mesh name="hip__1__1_mesh_5" file="roki/hip__1__1_mesh_5.obj"/>
    <mesh name="hip__1__2_mesh_0" file="roki/hip__1__2_mesh_0.obj"/>
    <mesh name="hip__1__2_mesh_1" file="roki/hip__1__2_mesh_1.obj"/>
    <mesh name="hip__1__2_mesh_2" file="roki/hip__1__2_mesh_2.obj"/>
    <mesh name="hip__1__2_mesh_3" file="roki/hip__1__2_mesh_3.obj"/>
    <mesh name="hip__1__2_mesh_4" file="roki/hip__1__2_mesh_4.obj"/>
    <mesh name="hip__1__2_mesh_5" file="roki/hip__1__2_mesh_5.obj"/>
    <mesh name="hip__2__1_mesh_0" file="roki/hip__2__1_mesh_0.obj"/>
    <mesh name="hip__2__1_mesh_1" file="roki/hip__2__1_mesh_1.obj"/>
    <mesh name="hip__2__1_mesh_2" file="roki/hip__2__1_mesh_2.obj"/>
    <mesh name="hip__2__1_mesh_3" file="roki/hip__2__1_mesh_3.obj"/>
    <mesh name="hip__2__1_mesh_4" file="roki/hip__2__1_mesh_4.obj"/>
    <mesh name="hip__2__1_mesh_5" file="roki/hip__2__1_mesh_5.obj"/>
    <mesh name="hip__2__3_mesh_0" file="roki/hip__2__3_mesh_0.obj"/>
    <mesh name="hip__2__3_mesh_1" file="roki/hip__2__3_mesh_1.obj"/>
    <mesh name="hip__2__3_mesh_2" file="roki/hip__2__3_mesh_2.obj"/>
    <mesh name="hip__2__3_mesh_3" file="roki/hip__2__3_mesh_3.obj"/>
    <mesh name="hip__2__3_mesh_4" file="roki/hip__2__3_mesh_4.obj"/>
    <mesh name="hip__2__3_mesh_5" file="roki/hip__2__3_mesh_5.obj"/>
    <mesh name="knee_1_mesh_0" file="roki/knee_1_mesh_0.obj"/>
    <mesh name="knee_1_mesh_1" file="roki/knee_1_mesh_1.obj"/>
    <mesh name="knee_1_mesh_2" file="roki/knee_1_mesh_2.obj"/>
    <mesh name="knee_1_mesh_3" file="roki/knee_1_mesh_3.obj"/>
    <mesh name="knee_1_mesh_4" file="roki/knee_1_mesh_4.obj"/>
    <mesh name="knee__1__1_mesh_0" file="roki/knee__1__1_mesh_0.obj"/>
    <mesh name="knee__1__1_mesh_1" file="roki/knee__1__1_mesh_1.obj"/>
    <mesh name="knee__1__1_mesh_2" file="roki/knee__1__1_mesh_2.obj"/>
    <mesh name="knee__1__1_mesh_3" file="roki/knee__1__1_mesh_3.obj"/>
    <mesh name="knee__1__1_mesh_4" file="roki/knee__1__1_mesh_4.obj"/>
    <mesh name="neck_1_mesh" file="roki/neck_1_mesh.obj"/>
    <mesh name="shin_2_mesh" file="roki/shin_2_mesh.obj"/>
    <mesh name="shin__1__1_mesh" file="roki/shin__1__1_mesh.obj"/>
    <mesh name="shin__2__1_mesh" file="roki/shin__2__1_mesh.obj"/>
    <mesh name="shin__3__1_mesh" file="roki/shin__3__1_mesh.obj"/>
    <mesh name="shoe_1_mesh_0" file="roki/shoe_1_mesh_0.obj"/>
    <mesh name="shoe_1_mesh_1" file="roki/shoe_1_mesh_1.obj"/>
    <mesh name="shoe_Mirror__1_mesh_0" file="roki/shoe_Mirror__1_mesh_0.obj"/>
    <mesh name="shoe_Mirror__1_mesh_1" file="roki/shoe_Mirror__1_mesh_1.obj"/>
    <mesh name="shoulder_1_mesh_0" file="roki/shoulder_1_mesh_0.obj"/>
    <mesh name="shoulder_1_mesh_1" file="roki/shoulder_1_mesh_1.obj"/>
    <mesh name="shoulder_1_mesh_2" file="roki/shoulder_1_mesh_2.obj"/>
    <mesh name="shoulder_1_mesh_3" file="roki/shoulder_1_mesh_3.obj"/>
    <mesh name="shoulder_u_1_mesh" file="roki/shoulder_u_1_mesh.obj"/>
    <mesh name="shoulder_u__1__1_mesh" file="roki/shoulder_u__1__1_mesh.obj"/>
    <mesh name="shoulder__1__1_mesh_0" file="roki/shoulder__1__1_mesh_0.obj"/>
    <mesh name="shoulder__1__1_mesh_1" file="roki/shoulder__1__1_mesh_1.obj"/>
    <mesh name="shoulder__1__1_mesh_2" file="roki/shoulder__1__1_mesh_2.obj"/>
    <mesh name="shoulder__1__1_mesh_3" file="roki/shoulder__1__1_mesh_3.obj"/>
    <mesh name="torso_1_mesh_0" file="roki/torso_1_mesh_0.obj"/>
    <mesh name="torso_1_mesh_1" file="roki/torso_1_mesh_1.obj"/>
    <mesh name="torso_1_mesh_2" file="roki/torso_1_mesh_2.obj"/>
    <mesh name="torso_1_mesh_3" file="roki/torso_1_mesh_3.obj"/>
    <mesh name="torso_1_mesh_4" file="roki/torso_1_mesh_4.obj"/>
    <mesh name="torso_1_mesh_5" file="roki/torso_1_mesh_5.obj"/>
    <mesh name="torso_1_mesh_6" file="roki/torso_1_mesh_6.obj"/>
    <mesh name="torso_1_mesh_7" file="roki/torso_1_mesh_7.obj"/>
    <mesh name="torso_1_mesh_8" file="roki/torso_1_mesh_8.obj"/>
    <mesh name="torso_1_mesh_9" file="roki/torso_1_mesh_9.obj"/>
    <mesh name="torso_1_mesh_10" file="roki/torso_1_mesh_10.obj"/>
    <mesh name="torso_1_mesh_11" file="roki/torso_1_mesh_11.obj"/>
    <mesh name="Waist_1_mesh_0" file="roki/Waist_1_mesh_0.obj"/>
    <mesh name="Waist_1_mesh_1" file="roki/Waist_1_mesh_1.obj"/>
    <mesh name="Waist_1_mesh_2" file="roki/Waist_1_mesh_2.obj"/>
    <mesh name="Waist_1_mesh_3" file="roki/Waist_1_mesh_3.obj"/>
    <mesh name="Waist_1_mesh_4" file="roki/Waist_1_mesh_4.obj"/>
  </asset>
  <worldbody>
    <geom name="floor" type="plane" pos="0 0 -0.285" size="5 5 0.001" material="groundplane"/>
    <body name="ball">
      <freejoint/>
        <geom type="sphere" pos="-0.16 -0.038 0.14" mass="0.06" size="0.01" friction="0.01 0.005 0.001" rgba="1 0 0 1"/>
    </body>
    <body name="torso_1" >
      <inertial pos="-0.0052174000000000005 0.0663892 0.0492326" quat="0.00163034 0.736044 -0.00202676 0.676928" mass="0.697847" diaginertia="0.00122454 0.000835755 0.000651356"/>
      <geom class="visual" pos="0.026286 0.06636 0.05495" quat="0 0.707107 -0.707107 0" material="Rubber_-_Soft" mesh="torso_1_mesh_0"/>
      <geom class="visual" pos="0.026286 0.06636 0.05495" quat="0 0.707107 -0.707107 0" material="Opaque(0,128,0)" mesh="torso_1_mesh_1"/>
      <geom class="visual" pos="0.026286 0.06636 0.05495" quat="0 0.707107 -0.707107 0" material="Opaque(0,0,255)" mesh="torso_1_mesh_2"/>
      <geom class="visual" pos="0.026286 0.06636 0.05495" quat="0 0.707107 -0.707107 0" material="ABS_(White)" mesh="torso_1_mesh_3"/>
      <geom class="visual" pos="0.026286 0.06636 0.05495" quat="0 0.707107 -0.707107 0" material="Generic" mesh="torso_1_mesh_4"/>
      <geom class="visual" pos="0.026286 0.06636 0.05495" quat="0 0.707107 -0.707107 0" material="Silver_-_Polished" mesh="torso_1_mesh_5"/>
      <geom class="visual" pos="0.026286 0.06636 0.05495" quat="0 0.707107 -0.707107 0" material="Plastic_-_Translucent_Glossy_(Red)" mesh="torso_1_mesh_6"/>
      <geom class="visual" pos="0.026286 0.06636 0.05495" quat="0 0.707107 -0.707107 0" material="Steel_-_Satin" mesh="torso_1_mesh_7"/>
      <geom class="visual" pos="0.026286 0.06636 0.05495" quat="0 0.707107 -0.707107 0" material="Titanium_-_Polished" mesh="torso_1_mesh_8"/>
      <geom class="visual" pos="0.026286 0.06636 0.05495" quat="0 0.707107 -0.707107 0" material="Aluminum_-_Anodized_Glossy_(Grey)" mesh="torso_1_mesh_9"/>
      <geom class="visual" pos="0.026286 0.06636 0.05495" quat="0 0.707107 -0.707107 0" material="Opaque(255,0,0)" mesh="torso_1_mesh_10"/>
      <geom class="visual" pos="0.026286 0.06636 0.05495" quat="0 0.707107 -0.707107 0" material="PA_12_-_Nylon_-_PA_603-CF_(with_EOS_P_3D_Printers)" mesh="torso_1_mesh_11"/>
      <geom class="collision" pos="0.026286 0.06636 0.05495" quat="0 0.707107 -0.707107 0" mesh="torso_1_mesh_0"/>
      <geom class="collision" pos="0.026286 0.06636 0.05495" quat="0 0.707107 -0.707107 0" mesh="torso_1_mesh_1"/>
      <geom class="collision" pos="0.026286 0.06636 0.05495" quat="0 0.707107 -0.707107 0" mesh="torso_1_mesh_2"/>
      <geom class="collision" pos="0.026286 0.06636 0.05495" quat="0 0.707107 -0.707107 0" mesh="torso_1_mesh_3"/>
      <!-- <geom class="collision" pos="0.026286 0.06636 0.05495" quat="0 0.707107 -0.707107 0" mesh="torso_1_mesh_4"/> -->
      <geom class="collision" pos="0.026286 0.06636 0.05495" quat="0 0.707107 -0.707107 0" mesh="torso_1_mesh_5"/>
      <geom class="collision" pos="0.026286 0.06636 0.05495" quat="0 0.707107 -0.707107 0" mesh="torso_1_mesh_6"/>
      <geom class="collision" pos="0.026286 0.06636 0.05495" quat="0 0.707107 -0.707107 0" mesh="torso_1_mesh_7"/>
      <geom class="collision" pos="0.026286 0.06636 0.05495" quat="0 0.707107 -0.707107 0" mesh="torso_1_mesh_8"/>
      <geom class="collision" pos="0.026286 0.06636 0.05495" quat="0 0.707107 -0.707107 0" mesh="torso_1_mesh_9"/>
      <geom class="collision" pos="0.026286 0.06636 0.05495" quat="0 0.707107 -0.707107 0" mesh="torso_1_mesh_10"/>
      <geom class="collision" pos="0.026286 0.06636 0.05495" quat="0 0.707107 -0.707107 0" mesh="torso_1_mesh_11"/>
      <body name="Waist_1">
        <inertial pos="0.016102199999999997 0.0663830895 -0.0156807" quat="0.531067 0.53082 -0.466871 0.467149" mass="0.157611" diaginertia="0.00019877 0.00018834 4.543e-05"/>
        <joint name="waist_yaw_joint" pos="0.026146 0.06636 0.0039" axis="0 0 -1" range="-0.349066 0.349066"/>
        <geom class="visual" pos="0.014835999999999998 0.06636 -0.0189" quat="0 0.707107 -0.707107 0" material="Steel_-_Satin" mesh="Waist_1_mesh_0"/>
        <geom class="visual" pos="0.014835999999999998 0.06636 -0.0189" quat="0 0.707107 -0.707107 0" material="Aluminum_-_Anodized_Glossy_(Grey)" mesh="Waist_1_mesh_1"/>
        <geom class="visual" pos="0.014835999999999998 0.06636 -0.0189" quat="0 0.707107 -0.707107 0" material="Titanium_-_Polished" mesh="Waist_1_mesh_2"/>
        <geom class="visual" pos="0.014835999999999998 0.06636 -0.0189" quat="0 0.707107 -0.707107 0" material="Carbon_Fiber_-_Plain" mesh="Waist_1_mesh_3"/>
        <geom class="visual" pos="0.014835999999999998 0.06636 -0.0189" quat="0 0.707107 -0.707107 0" material="PA_12_-_Nylon_-_PA_603-CF_(with_EOS_P_3D_Printers)" mesh="Waist_1_mesh_4"/>
        <geom class="collision" pos="0.014835999999999998 0.06636 -0.0189" quat="0 0.707107 -0.707107 0" mesh="Waist_1_mesh_0"/>
        <!-- <geom class="collision" pos="0.014835999999999998 0.06636 -0.0189" quat="0 0.707107 -0.707107 0" mesh="Waist_1_mesh_1"/> -->
        <!-- <geom class="collision" pos="0.014835999999999998 0.06636 -0.0189" quat="0 0.707107 -0.707107 0" mesh="Waist_1_mesh_2"/> -->
        <geom class="collision" pos="0.014835999999999998 0.06636 -0.0189" quat="0 0.707107 -0.707107 0" mesh="Waist_1_mesh_3"/>
        <!-- <geom class="collision" pos="0.014835999999999998 0.06636 -0.0189" quat="0 0.707107 -0.707107 0" mesh="Waist_1_mesh_4"/> -->
        <body name="hip_u_1">
          <inertial pos="0.030743939999999997 0.10636000000000001 -0.0442142" quat="0.499093 0.500905 0.500905 0.499093" mass="0.0095452" diaginertia="4.91e-06 4.25004e-06 1.48996e-06"/>
          <joint name="left_hip_yaw_joint" pos="0.026146 0.10636000000000001 -0.0339" axis="0 0 -1" range="-1.5708 1.5708"/>
          <geom class="visual" pos="0.026146 0.11105999999999999 -0.0339" quat="-0.5 0.5 -0.5 0.5" material="Generic" mesh="hip_u_1_mesh"/>
          <!-- <geom class="collision" pos="0.026146 0.11105999999999999 -0.0339" quat="-0.5 0.5 -0.5 0.5" mesh="hip_u_1_mesh"/> -->
          <body name="hip__1__2">
            <inertial pos="0.012081399999999999 0.1054026 -0.0771681" quat="0.552272 0.458712 0.453895 0.527786" mass="0.118522" diaginertia="8.2823e-05 7.34712e-05 3.21558e-05"/>
            <joint name="left_hip_roll_joint" pos="0.026146 0.10636000000000001 -0.0659" axis="1 0 0" range="-1.5708 1.5708"/>
            <geom class="visual" pos="-0.017754000000000002 0.10636000000000001 -0.05459" quat="0.5 0.5 -0.5 -0.5" material="Aluminum_-_Bead_Blasted" mesh="hip__1__2_mesh_0"/>
            <geom class="visual" pos="-0.017754000000000002 0.10636000000000001 -0.05459" quat="0.5 0.5 -0.5 -0.5" material="Carbon_Fiber_-_Plain" mesh="hip__1__2_mesh_1"/>
            <geom class="visual" pos="-0.017754000000000002 0.10636000000000001 -0.05459" quat="0.5 0.5 -0.5 -0.5" material="PA_12_-_Nylon_-_PA_603-CF_(with_EOS_P_3D_Printers)" mesh="hip__1__2_mesh_2"/>
            <geom class="visual" pos="-0.017754000000000002 0.10636000000000001 -0.05459" quat="0.5 0.5 -0.5 -0.5" material="Steel_-_Satin" mesh="hip__1__2_mesh_3"/>
            <geom class="visual" pos="-0.017754000000000002 0.10636000000000001 -0.05459" quat="0.5 0.5 -0.5 -0.5" material="Aluminum_-_Anodized_Glossy_(Grey)" mesh="hip__1__2_mesh_4"/>
            <geom class="visual" pos="-0.017754000000000002 0.10636000000000001 -0.05459" quat="0.5 0.5 -0.5 -0.5" material="Titanium_-_Polished" mesh="hip__1__2_mesh_5"/>
            <geom class="collision" pos="-0.017754000000000002 0.10636000000000001 -0.05459" quat="0.5 0.5 -0.5 -0.5" mesh="hip__1__2_mesh_0"/>
            <geom class="collision" pos="-0.017754000000000002 0.10636000000000001 -0.05459" quat="0.5 0.5 -0.5 -0.5" mesh="hip__1__2_mesh_1"/>
            <geom class="collision" pos="-0.017754000000000002 0.10636000000000001 -0.05459" quat="0.5 0.5 -0.5 -0.5" mesh="hip__1__2_mesh_2"/>
            <geom class="collision" pos="-0.017754000000000002 0.10636000000000001 -0.05459" quat="0.5 0.5 -0.5 -0.5" mesh="hip__1__2_mesh_3"/>
            <geom class="collision" pos="-0.017754000000000002 0.10636000000000001 -0.05459" quat="0.5 0.5 -0.5 -0.5" mesh="hip__1__2_mesh_4"/>
            <geom class="collision" pos="-0.017754000000000002 0.10636000000000001 -0.05459" quat="0.5 0.5 -0.5 -0.5" mesh="hip__1__2_mesh_5"/>
            <body name="shin_2">
              <inertial pos="0.03524951 0.10596 -0.110474" quat="0.996718 0 -0.0809543 0" mass="0.0226254" diaginertia="1.85601e-05 1.272e-05 1.20299e-05"/>
              <joint name="left_hip_pitch_joint" pos="0.026146 0.10636000000000001 -0.0659" axis="0 1 0" range="-1.74533 1.0472"/>
              <geom class="visual" pos="-0.014104000000000002 0.10596 -0.0899" quat="0.5 0.5 -0.5 -0.5" material="Generic" mesh="shin_2_mesh"/>
              <geom class="collision" pos="0.055146 0.10636000000000001 -0.115" quat="0.5 0.5 -0.5 -0.5" type="box" size="0.02 0.015 0.0015"/>


              <!-- <geom class="collision" pos="-0.014104000000000002 0.10596 -0.0899" quat="0.5 0.5 -0.5 -0.5" mesh="shin_2_mesh"/> -->
              <body name="knee_1">
                <inertial pos="0.0364763 0.1045709 -0.164967" quat="0.704901 -0.00128061 0.000461048 0.709304" mass="0.109303" diaginertia="5.34902e-05 5.02699e-05 3.31699e-05"/>
                <joint name="left_upper_knee_joint" pos="0.026146 0.10636000000000001 -0.1484" axis="0 1 0" range="-0.087266 2.0944"/>
                <geom class="visual" pos="-0.042654 -0.09364 -0.1164" quat="0.5 -0.5 -0.5 0.5" material="Generic" mesh="knee_1_mesh_0"/>
                <geom class="visual" pos="-0.042654 -0.09364 -0.1164" quat="0.5 -0.5 -0.5 0.5" material="PA_12_-_Nylon_-_PA_603-CF_(with_EOS_P_3D_Printers)" mesh="knee_1_mesh_1"/>
                <geom class="visual" pos="-0.042654 -0.09364 -0.1164" quat="0.5 -0.5 -0.5 0.5" material="Steel_-_Satin" mesh="knee_1_mesh_2"/>
                <geom class="visual" pos="-0.042654 -0.09364 -0.1164" quat="0.5 -0.5 -0.5 0.5" material="Aluminum_-_Anodized_Glossy_(Grey)" mesh="knee_1_mesh_3"/>
                <geom class="visual" pos="-0.042654 -0.09364 -0.1164" quat="0.5 -0.5 -0.5 0.5" material="Titanium_-_Polished" mesh="knee_1_mesh_4"/>
                <geom class="collision" pos="-0.042654 -0.09364 -0.1164" quat="0.5 -0.5 -0.5 0.5" mesh="knee_1_mesh_0"/>
                <geom class="collision" pos="-0.042654 -0.09364 -0.1164" quat="0.5 -0.5 -0.5 0.5" mesh="knee_1_mesh_1"/>
                <geom class="collision" pos="-0.042654 -0.09364 -0.1164" quat="0.5 -0.5 -0.5 0.5" mesh="knee_1_mesh_2"/>
                <geom class="collision" pos="-0.042654 -0.09364 -0.1164" quat="0.5 -0.5 -0.5 0.5" mesh="knee_1_mesh_3"/>
                <geom class="collision" pos="-0.042654 -0.09364 -0.1164" quat="0.5 -0.5 -0.5 0.5" mesh="knee_1_mesh_4"/>
                <body name="shin__2__1">
                  <inertial pos="0.03524951 0.10596 -0.219326" quat="0.996718 0 0.0809543 0" mass="0.0226254" diaginertia="1.85601e-05 1.272e-05 1.20299e-05"/>
                  <joint name="left_bottom_knee_joint" pos="0.026146 0.10636000000000001 -0.1814" axis="0 1 0" range="0 2.44346"/>
                  <geom class="visual" pos="-0.014104000000000002 0.10596 -0.2399" quat="-0.5 0.5 0.5 -0.5" material="Generic" mesh="shin__2__1_mesh"/>
                  <geom class="collision" pos="0.055146 0.10636000000000001 -0.214" quat="0.5 0.5 -0.5 -0.5" type="box" size="0.02 0.015 0.0015"/>

                  
                  <!-- <geom class="collision" pos="-0.014104000000000002 0.10596 -0.2399" quat="-0.5 0.5 0.5 -0.5" mesh="shin__2__1_mesh"/> -->
                  <body name="hip__2__1">
                    <inertial pos="0.0121429 0.1054647 -0.252634" quat="0.459424 0.55344 0.526146 0.453656" mass="0.118522" diaginertia="8.30649e-05 7.36944e-05 3.21707e-05"/>
                    <joint name="left_ankle_pitch_joint" pos="0.026146 0.10636000000000001 -0.2639" axis="0 1 0" range="-1.17 1.13446"/>
                    <geom class="visual" pos="-0.017754000000000002 0.10636000000000001 -0.27521" quat="-0.5 0.5 0.5 -0.5" material="Carbon_Fiber_-_Plain" mesh="hip__2__1_mesh_0"/>
                    <geom class="visual" pos="-0.017754000000000002 0.10636000000000001 -0.27521" quat="-0.5 0.5 0.5 -0.5" material="Aluminum_-_Bead_Blasted" mesh="hip__2__1_mesh_1"/>
                    <geom class="visual" pos="-0.017754000000000002 0.10636000000000001 -0.27521" quat="-0.5 0.5 0.5 -0.5" material="PA_12_-_Nylon_-_PA_603-CF_(with_EOS_P_3D_Printers)" mesh="hip__2__1_mesh_2"/>
                    <geom class="visual" pos="-0.017754000000000002 0.10636000000000001 -0.27521" quat="-0.5 0.5 0.5 -0.5" material="Steel_-_Satin" mesh="hip__2__1_mesh_3"/>
                    <geom class="visual" pos="-0.017754000000000002 0.10636000000000001 -0.27521" quat="-0.5 0.5 0.5 -0.5" material="Aluminum_-_Anodized_Glossy_(Grey)" mesh="hip__2__1_mesh_4"/>
                    <geom class="visual" pos="-0.017754000000000002 0.10636000000000001 -0.27521" quat="-0.5 0.5 0.5 -0.5" material="Titanium_-_Polished" mesh="hip__2__1_mesh_5"/>
                    <geom class="collision" pos="-0.017754000000000002 0.10636000000000001 -0.27521" quat="-0.5 0.5 0.5 -0.5" mesh="hip__2__1_mesh_0"/>
                    <geom class="collision" pos="-0.017754000000000002 0.10636000000000001 -0.27521" quat="-0.5 0.5 0.5 -0.5" mesh="hip__2__1_mesh_1"/>
                    <geom class="collision" pos="-0.017754000000000002 0.10636000000000001 -0.27521" quat="-0.5 0.5 0.5 -0.5" mesh="hip__2__1_mesh_2"/>
                    <geom class="collision" pos="-0.017754000000000002 0.10636000000000001 -0.27521" quat="-0.5 0.5 0.5 -0.5" mesh="hip__2__1_mesh_3"/>
                    <geom class="collision" pos="-0.017754000000000002 0.10636000000000001 -0.27521" quat="-0.5 0.5 0.5 -0.5" mesh="hip__2__1_mesh_4"/>
                    <geom class="collision" pos="-0.017754000000000002 0.10636000000000001 -0.27521" quat="-0.5 0.5 0.5 -0.5" mesh="hip__2__1_mesh_5"/>
                    <body name="shoe_Mirror__1">
                      <inertial pos="0.026988074 0.117132 -0.284326" quat="0.0190303 0.705028 0.00629055 0.708896" mass="0.0509853" diaginertia="6.62964e-05 4.68333e-05 2.09503e-05"/>
                      <joint name="left_ankle_roll_joint" pos="0.026146 0.10636000000000001 -0.2639" axis="1 0 0" range="-0.523599 0.349066"/>
                      <geom class="visual" pos="0.026146 0.19776 -0.2877" quat="0.707107 0 0 0.707107" material="Generic" mesh="shoe_Mirror__1_mesh_0"/>
                      <geom class="visual" pos="0.026146 0.19776 -0.2877" quat="0.707107 0 0 0.707107" material="Rubber_-_Soft" mesh="shoe_Mirror__1_mesh_1"/>
                      <geom class="collision" pos="0.035546 0.12136 -0.2837" quat="0.707107 0 0 -0.707107" type="box" size="0.04 0.057 0.004"/>

                      <!-- <geom class="collision" pos="0.026146 0.19776 -0.2877" quat="0.707107 0 0 0.707107" mesh="shoe_Mirror__1_mesh_0"/>
                      <geom class="collision" pos="0.026146 0.19776 -0.2877" quat="0.707107 0 0 0.707107" mesh="shoe_Mirror__1_mesh_1"/> -->
                    </body>
                  </body>
                </body>
              </body>
            </body>
          </body>
        </body>
        <body name="hip_u_3">
          <inertial pos="0.030743939999999997 0.02636 -0.0442142" quat="0.499093 0.500905 0.500905 0.499093" mass="0.0095452" diaginertia="4.91e-06 4.25004e-06 1.48996e-06"/>
          <joint name="right_hip_yaw_joint" pos="0.026146 0.02636 -0.0339" axis="0 0 -1" range="-1.5708 1.5708"/>
          <geom class="visual" pos="0.026146 0.031060000000000004 -0.0339" quat="-0.5 0.5 -0.5 0.5" material="Generic" mesh="hip_u_3_mesh"/>
          <!-- <geom name="roki//unnamed_geom_2" pos="0 -0.4 0"  class="visual" type="mesh"  mesh="U_Dual_Lever_Carbon_1_"/> -->
          <!-- <geom class="collision" pos="0.026146 0.031060000000000004 -0.0339" quat="-0.5 0.5 -0.5 0.5" mesh="hip_u_3_mesh"/> -->
          <body name="hip__2__3">
            <inertial pos="0.0121429 0.027255300000000003 -0.0771659" quat="0.526146 0.453656 0.459424 0.55344" mass="0.118522" diaginertia="8.30649e-05 7.36944e-05 3.21707e-05"/>
            <joint name="right_hip_roll_joint" pos="0.026146 0.02636 -0.0659" axis="1 0 0" range="-1.5708 1.5708"/>
            <geom class="visual" pos="-0.017754000000000002 0.02636 -0.05459" quat="0.5 0.5 -0.5 -0.5" material="Carbon_Fiber_-_Plain" mesh="hip__2__3_mesh_0"/>
            <geom class="visual" pos="-0.017754000000000002 0.02636 -0.05459" quat="0.5 0.5 -0.5 -0.5" material="Aluminum_-_Bead_Blasted" mesh="hip__2__3_mesh_1"/>
            <geom class="visual" pos="-0.017754000000000002 0.02636 -0.05459" quat="0.5 0.5 -0.5 -0.5" material="PA_12_-_Nylon_-_PA_603-CF_(with_EOS_P_3D_Printers)" mesh="hip__2__3_mesh_2"/>
            <geom class="visual" pos="-0.017754000000000002 0.02636 -0.05459" quat="0.5 0.5 -0.5 -0.5" material="Steel_-_Satin" mesh="hip__2__3_mesh_3"/>
            <geom class="visual" pos="-0.017754000000000002 0.02636 -0.05459" quat="0.5 0.5 -0.5 -0.5" material="Aluminum_-_Anodized_Glossy_(Grey)" mesh="hip__2__3_mesh_4"/>
            <geom class="visual" pos="-0.017754000000000002 0.02636 -0.05459" quat="0.5 0.5 -0.5 -0.5" material="Titanium_-_Polished" mesh="hip__2__3_mesh_5"/>
            <geom class="collision" pos="-0.017754000000000002 0.02636 -0.05459" quat="0.5 0.5 -0.5 -0.5" mesh="hip__2__3_mesh_0"/>
            <geom class="collision" pos="-0.017754000000000002 0.02636 -0.05459" quat="0.5 0.5 -0.5 -0.5" mesh="hip__2__3_mesh_1"/>
            <geom class="collision" pos="-0.017754000000000002 0.02636 -0.05459" quat="0.5 0.5 -0.5 -0.5" mesh="hip__2__3_mesh_2"/>
            <geom class="collision" pos="-0.017754000000000002 0.02636 -0.05459" quat="0.5 0.5 -0.5 -0.5" mesh="hip__2__3_mesh_3"/>
            <geom class="collision" pos="-0.017754000000000002 0.02636 -0.05459" quat="0.5 0.5 -0.5 -0.5" mesh="hip__2__3_mesh_4"/>
            <geom class="collision" pos="-0.017754000000000002 0.02636 -0.05459" quat="0.5 0.5 -0.5 -0.5" mesh="hip__2__3_mesh_5"/>
            <body name="shin__3__1">
              <inertial pos="0.03524951 0.02676 -0.110474" quat="0.996718 0 -0.0809543 0" mass="0.0226254" diaginertia="1.85601e-05 1.272e-05 1.20299e-05"/>
              <joint name="right_hip_pitch_joint" pos="0.026146 0.02636 -0.0659" axis="0 1 0" range="-1.74533 1.0472"/>
              <geom class="visual" pos="-0.014104000000000002 0.02676 -0.0899" quat="0.5 0.5 -0.5 -0.5" material="Generic" mesh="shin__3__1_mesh"/>
              <geom class="collision" pos="0.055146 0.02636 -0.115" quat="0.5 0.5 -0.5 -0.5" type="box" size="0.02 0.015 0.0015"/>

              <!-- <geom class="collision" pos="-0.014104000000000002 0.02676 -0.0899" quat="0.5 0.5 -0.5 -0.5" mesh="shin__3__1_mesh"/> -->
              <body name="knee__1__1">
                <inertial pos="0.0364763 0.028149100000000003 -0.164833" quat="0.709304 -0.000461048 0.00128061 0.704901" mass="0.109303" diaginertia="5.34902e-05 5.02699e-05 3.31699e-05"/>
                <joint name="right_upper_knee_joint" pos="0.026146 0.02636 -0.1484" axis="0 1 0" range="-0.087266 2.0944"/>
                <geom class="visual" pos="-0.042654 0.22636 -0.2134" quat="0.5 0.5 -0.5 -0.5" material="Generic" mesh="knee__1__1_mesh_0"/>
                <geom class="visual" pos="-0.042654 0.22636 -0.2134" quat="0.5 0.5 -0.5 -0.5" material="PA_12_-_Nylon_-_PA_603-CF_(with_EOS_P_3D_Printers)" mesh="knee__1__1_mesh_1"/>
                <geom class="visual" pos="-0.042654 0.22636 -0.2134" quat="0.5 0.5 -0.5 -0.5" material="Steel_-_Satin" mesh="knee__1__1_mesh_2"/>
                <geom class="visual" pos="-0.042654 0.22636 -0.2134" quat="0.5 0.5 -0.5 -0.5" material="Aluminum_-_Anodized_Glossy_(Grey)" mesh="knee__1__1_mesh_3"/>
                <geom class="visual" pos="-0.042654 0.22636 -0.2134" quat="0.5 0.5 -0.5 -0.5" material="Titanium_-_Polished" mesh="knee__1__1_mesh_4"/>
                <geom class="collision" pos="-0.042654 0.22636 -0.2134" quat="0.5 0.5 -0.5 -0.5" mesh="knee__1__1_mesh_0"/>
                <geom class="collision" pos="-0.042654 0.22636 -0.2134" quat="0.5 0.5 -0.5 -0.5" mesh="knee__1__1_mesh_1"/>
                <geom class="collision" pos="-0.042654 0.22636 -0.2134" quat="0.5 0.5 -0.5 -0.5" mesh="knee__1__1_mesh_2"/>
                <geom class="collision" pos="-0.042654 0.22636 -0.2134" quat="0.5 0.5 -0.5 -0.5" mesh="knee__1__1_mesh_3"/>
                <geom class="collision" pos="-0.042654 0.22636 -0.2134" quat="0.5 0.5 -0.5 -0.5" mesh="knee__1__1_mesh_4"/>
                <body name="shin__1__1">
                  <inertial pos="0.03524951 0.02676 -0.219326" quat="0.996718 0 0.0809543 0" mass="0.0226254" diaginertia="1.85601e-05 1.272e-05 1.20299e-05"/>
                  <joint name="right_bottom_knee_joint" pos="0.026146 0.02636 -0.1814" axis="0 1 0" range="0 2.44346"/>
                  <geom class="visual" pos="-0.014104000000000002 0.02676 -0.2399" quat="-0.5 0.5 0.5 -0.5" material="Generic" mesh="shin__1__1_mesh"/>
                  <geom class="collision" pos="0.055146 0.02636 -0.214" quat="0.5 0.5 -0.5 -0.5" type="box" size="0.02 0.015 0.0015"/>

                  <!-- <geom class="collision" pos="-0.014104000000000002 0.02676 -0.2399" quat="-0.5 0.5 0.5 -0.5" mesh="shin__1__1_mesh"/> -->
                  <body name="hip__1__1">
                    <inertial pos="0.012081399999999999 0.027317400000000006 -0.252632" quat="0.453895 0.527786 0.552272 0.458712" mass="0.118522" diaginertia="8.2823e-05 7.34712e-05 3.21558e-05"/>
                    <joint name="right_ankle_pitch_joint" pos="0.026146 0.02636 -0.2639" axis="0 1 0" range="-1.17 1.13446"/>
                    <geom class="visual" pos="-0.017754000000000002 0.02636 -0.27521" quat="-0.5 0.5 0.5 -0.5" material="Aluminum_-_Bead_Blasted" mesh="hip__1__1_mesh_0"/>
                    <geom class="visual" pos="-0.017754000000000002 0.02636 -0.27521" quat="-0.5 0.5 0.5 -0.5" material="Carbon_Fiber_-_Plain" mesh="hip__1__1_mesh_1"/>
                    <geom class="visual" pos="-0.017754000000000002 0.02636 -0.27521" quat="-0.5 0.5 0.5 -0.5" material="PA_12_-_Nylon_-_PA_603-CF_(with_EOS_P_3D_Printers)" mesh="hip__1__1_mesh_2"/>
                    <geom class="visual" pos="-0.017754000000000002 0.02636 -0.27521" quat="-0.5 0.5 0.5 -0.5" material="Steel_-_Satin" mesh="hip__1__1_mesh_3"/>
                    <geom class="visual" pos="-0.017754000000000002 0.02636 -0.27521" quat="-0.5 0.5 0.5 -0.5" material="Aluminum_-_Anodized_Glossy_(Grey)" mesh="hip__1__1_mesh_4"/>
                    <geom class="visual" pos="-0.017754000000000002 0.02636 -0.27521" quat="-0.5 0.5 0.5 -0.5" material="Titanium_-_Polished" mesh="hip__1__1_mesh_5"/>
                    <geom class="collision" pos="-0.017754000000000002 0.02636 -0.27521" quat="-0.5 0.5 0.5 -0.5" mesh="hip__1__1_mesh_0"/>
                    <geom class="collision" pos="-0.017754000000000002 0.02636 -0.27521" quat="-0.5 0.5 0.5 -0.5" mesh="hip__1__1_mesh_1"/>
                    <geom class="collision" pos="-0.017754000000000002 0.02636 -0.27521" quat="-0.5 0.5 0.5 -0.5" mesh="hip__1__1_mesh_2"/>
                    <geom class="collision" pos="-0.017754000000000002 0.02636 -0.27521" quat="-0.5 0.5 0.5 -0.5" mesh="hip__1__1_mesh_3"/>
                    <geom class="collision" pos="-0.017754000000000002 0.02636 -0.27521" quat="-0.5 0.5 0.5 -0.5" mesh="hip__1__1_mesh_4"/>
                    <geom class="collision" pos="-0.017754000000000002 0.02636 -0.27521" quat="-0.5 0.5 0.5 -0.5" mesh="hip__1__1_mesh_5"/>
                    <body name="shoe_1">
                      <inertial pos="0.026988066999999998 0.015588000000000005 -0.284326" quat="-0.0190303 0.705028 -0.00629055 0.708896" mass="0.0509852" diaginertia="6.62964e-05 4.68333e-05 2.09503e-05"/>
                      <joint name="right_ankle_roll_joint" pos="0.026146 0.02636 -0.2639" axis="1 0 0" range="-0.523599 0.349066"/>
                      <geom class="visual" pos="0.026146 -0.06503999999999999 -0.2877" quat="0 0.707107 -0.707107 0" material="Generic" mesh="shoe_1_mesh_0"/>
                      <geom class="visual" pos="0.026146 -0.06503999999999999 -0.2877" quat="0 0.707107 -0.707107 0" material="Rubber_-_Soft" mesh="shoe_1_mesh_1"/>
                      <geom class="collision" pos="0.035546 0.011360000000000002 -0.2837" quat="0.707107 0 0 -0.707107" type="box" size="0.04 0.057 0.004"/>

                      <!-- <geom class="collision" pos="0.026146 -0.06503999999999999 -0.2877" quat="0 0.707107 -0.707107 0" mesh="shoe_1_mesh_0"/> -->
                      <!-- <geom class="collision" pos="0.026146 -0.06503999999999999 -0.2877" quat="0 0.707107 -0.707107 0" mesh="shoe_1_mesh_1"/> -->
                    </body>
                  </body>
                </body>
              </body>
            </body>
          </body>
        </body>
      </body>
      <body name="neck_1">
        <inertial pos="0.0368951 0.06638515910000001 0.0836729" quat="0.706925 0.706925 -0.0160252 0.0160252" mass="0.00688992" diaginertia="2.76045e-06 2.53955e-06 1.08e-06"/>
        <joint name="head_yaw_joint" pos="0.037298 0.066385 0.07478" axis="0 0 1" range="-0.785398 0.785398"/>
        <geom class="visual" pos="0.037298 0.066385 0.07478" quat="0.5 0.5 -0.5 -0.5" material="Carbon_Fiber_-_Plain" mesh="neck_1_mesh"/>
        <!-- <geom class="collision" pos="0.037298 0.066385 0.07478" quat="0.5 0.5 -0.5 -0.5" mesh="neck_1_mesh"/> -->
        <body name="head_1">
          <inertial pos="0.021803959999999997 0.065609048 0.139029" quat="0.917176 0.0499205 -0.352933 -0.17814" mass="0.264163" diaginertia="0.000259053 0.000252375 0.000192032"/>
          <joint name="head_pitch_joint" pos="0.037298 0.06636 0.10478" axis="0 1 0" range="-1.91986 0.698132"/>
          <camera name="camera" pos="0.036146 0.066285 0.1577" quat="0.5 0.5 -0.5 -0.5"/>

          <geom class="visual" pos="0.058648000000000006 0.066285 0.064305" quat="0.5 -0.5 -0.5 0.5" material="Opaque(0,128,0)" mesh="head_1_mesh_0"/>
          <geom class="visual" pos="0.058648000000000006 0.066285 0.064305" quat="0.5 -0.5 -0.5 0.5" material="Rubber_-_Soft" mesh="head_1_mesh_1"/>
          <geom class="visual" pos="0.058648000000000006 0.066285 0.064305" quat="0.5 -0.5 -0.5 0.5" material="Opaque(0,0,255)" mesh="head_1_mesh_2"/>
          <geom class="visual" pos="0.058648000000000006 0.066285 0.064305" quat="0.5 -0.5 -0.5 0.5" material="Opaque(255,0,0)" mesh="head_1_mesh_3"/>
          <geom class="visual" pos="0.058648000000000006 0.066285 0.064305" quat="0.5 -0.5 -0.5 0.5" material="Silver_-_Polished" mesh="head_1_mesh_4"/>
          <!-- <geom class="visual" pos="0.058648000000000006 0.066285 0.064305" quat="0.5 -0.5 -0.5 0.5" material="Opaque(192,255,255)" mesh="head_1_mesh_5"/> -->
          <geom type="sphere" class="visual" pos="0.028145999999999997 0.066285 0.1577" quat="0.5 -0.5 -0.5 0.5" material="Opaque(192,255,255)"  size="0.025 0.025 0.025"/>
          <geom class="visual" pos="0.028145999999999997 0.066285 0.1577" quat="0.5 -0.5 -0.5 0.5" rgba="0 0 0 1" type="box" size="0.022 0.022 0.015"/>


          <geom class="visual" pos="0.058648000000000006 0.066285 0.064305" quat="0.5 -0.5 -0.5 0.5" material="Aluminum_-_Satin" mesh="head_1_mesh_6"/>
          <geom class="visual" pos="0.058648000000000006 0.066285 0.064305" quat="0.5 -0.5 -0.5 0.5" material="Opaque(76,76,76)" mesh="head_1_mesh_7"/>
          <geom class="visual" pos="0.058648000000000006 0.066285 0.064305" quat="0.5 -0.5 -0.5 0.5" material="Steel_-_Satin" mesh="head_1_mesh_8"/>
          <!-- <geom class="visual" pos="0.058648000000000006 0.066285 0.064305" quat="0.5 -0.5 -0.5 0.5" material="Glass_(Clear)" mesh="head_1_mesh_9"/> -->
          <geom class="visual" pos="0.053166 0.06636 0.1138" quat="0.5 -0.5 -0.5 0.5" type="box" material="Opaque(192,255,255)"  size="0.014 0.014 0.005"/>

          <geom class="visual" pos="0.058648000000000006 0.066285 0.064305" quat="0.5 -0.5 -0.5 0.5" material="ABS_(White)" mesh="head_1_mesh_10"/>
          <geom class="visual" pos="0.058648000000000006 0.066285 0.064305" quat="0.5 -0.5 -0.5 0.5" material="PA_12_-_Nylon_-_PA_603-CF_(with_EOS_P_3D_Printers)" mesh="head_1_mesh_11"/>
          <geom class="collision" pos="0.058648000000000006 0.066285 0.064305" quat="0.5 -0.5 -0.5 0.5" mesh="head_1_mesh_0"/>
          <geom class="collision" pos="0.058648000000000006 0.066285 0.064305" quat="0.5 -0.5 -0.5 0.5" mesh="head_1_mesh_1"/>
          <geom class="collision" pos="0.058648000000000006 0.066285 0.064305" quat="0.5 -0.5 -0.5 0.5" mesh="head_1_mesh_2"/>
          <geom class="collision" pos="0.058648000000000006 0.066285 0.064305" quat="0.5 -0.5 -0.5 0.5" mesh="head_1_mesh_3"/>
          <geom class="collision" pos="0.058648000000000006 0.066285 0.064305" quat="0.5 -0.5 -0.5 0.5" mesh="head_1_mesh_4"/>
          <geom class="collision" pos="0.058648000000000006 0.066285 0.064305" quat="0.5 -0.5 -0.5 0.5" mesh="head_1_mesh_5"/>
          <geom class="collision" pos="0.058648000000000006 0.066285 0.064305" quat="0.5 -0.5 -0.5 0.5" mesh="head_1_mesh_6"/>
          <geom class="collision" pos="0.058648000000000006 0.066285 0.064305" quat="0.5 -0.5 -0.5 0.5" mesh="head_1_mesh_7"/>
          <geom class="collision" pos="0.058648000000000006 0.066285 0.064305" quat="0.5 -0.5 -0.5 0.5" mesh="head_1_mesh_8"/>
          <geom class="collision" pos="0.058648000000000006 0.066285 0.064305" quat="0.5 -0.5 -0.5 0.5" mesh="head_1_mesh_9"/>
          <geom class="collision" pos="0.058648000000000006 0.066285 0.064305" quat="0.5 -0.5 -0.5 0.5" mesh="head_1_mesh_10"/>
          <geom class="collision" pos="0.058648000000000006 0.066285 0.064305" quat="0.5 -0.5 -0.5 0.5" mesh="head_1_mesh_11"/>
        </body>
      </body>
      <body name="shoulder_u_1">
        <inertial pos="0.037356 0.12997419999999998 0.0494" quat="0 0.707107 0 0.707107" mass="0.00757239" diaginertia="2.73e-06 2.6e-06 8.3e-07"/>
        <joint name="left_shoulder_pitch_joint" pos="0.037356 0.12226000000000001 0.0494" axis="0 1 0" range="-3.14159 3.14159"/>
        <geom class="visual" pos="0.037356 0.12226000000000001 0.0494" quat="0.707107 0 0.707107 0" material="Generic" mesh="shoulder_u_1_mesh"/>
        <!-- <geom class="collision" pos="0.037356 0.12226000000000001 0.0494" quat="0.707107 0 0.707107 0" mesh="shoulder_u_1_mesh"/> -->
        <body name="shoulder_1">
          <inertial pos="0.02917454 0.1521459 0.0160243" quat="0.681999 0.186859 0.0655843 0.704031" mass="0.129837" diaginertia="9.56099e-05 8.39302e-05 2.49599e-05"/>
          <joint name="left_shoulder_roll_joint" pos="0.037356 0.14626 0.0494" axis="1 0 0" range="-0.349066 2.96706"/>
          <geom class="visual" pos="0.037456 0.14626 0.0494" quat="0.707107 0 0.707107 0" material="PA_12_-_Nylon_-_PA_603-CF_(with_EOS_P_3D_Printers)" mesh="shoulder_1_mesh_0"/>
          <geom class="visual" pos="0.037456 0.14626 0.0494" quat="0.707107 0 0.707107 0" material="Carbon_Fiber_-_Plain" mesh="shoulder_1_mesh_1"/>
          <geom class="visual" pos="0.037456 0.14626 0.0494" quat="0.707107 0 0.707107 0" material="Aluminum_-_Anodized_Glossy_(Grey)" mesh="shoulder_1_mesh_2"/>
          <geom class="visual" pos="0.037456 0.14626 0.0494" quat="0.707107 0 0.707107 0" material="Aluminum_-_Satin" mesh="shoulder_1_mesh_3"/>
          <geom class="collision" pos="0.037456 0.14626 0.0494" quat="0.707107 0 0.707107 0" mesh="shoulder_1_mesh_0"/>
          <geom class="collision" pos="0.037456 0.14626 0.0494" quat="0.707107 0 0.707107 0" mesh="shoulder_1_mesh_1"/>
          <geom class="collision" pos="0.037456 0.14626 0.0494" quat="0.707107 0 0.707107 0" mesh="shoulder_1_mesh_2"/>
          <geom class="collision" pos="0.037456 0.14626 0.0494" quat="0.707107 0 0.707107 0" mesh="shoulder_1_mesh_3"/>
          <body name="elbow_1">
            <inertial pos="0.0337641 0.16279749999999998 -0.0381547" quat="-0.0531654 0.702835 -0.0580224 0.706986" mass="0.0555309" diaginertia="1.58702e-05 1.18001e-05 1.09898e-05"/>
            <joint name="left_elbow_yaw_joint" pos="0.034781 0.15875 -0.021432" axis="0 0.173648 -0.984808" range="-1.5708 1.5708"/>
            <geom class="visual" pos="0.011959999999999998 0.243054 -0.073939" quat="0.454519 0.541675 0.454519 0.541675" material="Generic" mesh="elbow_1_mesh_0"/>
            <geom class="visual" pos="0.011959999999999998 0.243054 -0.073939" quat="0.454519 0.541675 0.454519 0.541675" material="PA_12_-_Nylon_-_PA_603-CF_(with_EOS_P_3D_Printers)" mesh="elbow_1_mesh_1"/>
            <geom class="visual" pos="0.011959999999999998 0.243054 -0.073939" quat="0.454519 0.541675 0.454519 0.541675" material="Steel_-_Satin" mesh="elbow_1_mesh_2"/>
            <geom class="visual" pos="0.011959999999999998 0.243054 -0.073939" quat="0.454519 0.541675 0.454519 0.541675" material="Aluminum_-_Anodized_Glossy_(Grey)" mesh="elbow_1_mesh_3"/>
            <geom class="visual" pos="0.011959999999999998 0.243054 -0.073939" quat="0.454519 0.541675 0.454519 0.541675" material="Titanium_-_Polished" mesh="elbow_1_mesh_4"/>
            <geom class="collision" pos="0.011959999999999998 0.243054 -0.073939" quat="0.454519 0.541675 0.454519 0.541675" mesh="elbow_1_mesh_0"/>
            <geom class="collision" pos="0.011959999999999998 0.243054 -0.073939" quat="0.454519 0.541675 0.454519 0.541675" mesh="elbow_1_mesh_1"/>
            <geom class="collision" pos="0.011959999999999998 0.243054 -0.073939" quat="0.454519 0.541675 0.454519 0.541675" mesh="elbow_1_mesh_2"/>
            <geom class="collision" pos="0.011959999999999998 0.243054 -0.073939" quat="0.454519 0.541675 0.454519 0.541675" mesh="elbow_1_mesh_3"/>
            <geom class="collision" pos="0.011959999999999998 0.243054 -0.073939" quat="0.454519 0.541675 0.454519 0.541675" mesh="elbow_1_mesh_4"/>
            <body name="elbow_u_1">
              <!-- <inertial pos="0.042681 0.167264 -0.0547457" quat="0.643581 0.765378 0 0" mass="0.00757239" diaginertia="2.73e-06 2.60226e-06 8.27743e-07"/> -->
              <joint name="left_elbow_pitch_joint" pos="0.042681 0.14474 -0.04218" axis="0 0.984808 0.173648" range="-2.61799 0.174533"/>
              <geom class="visual" pos="0.042681 0.159226 -0.009163" quat="0.996195 0.087156 0 0" material="Generic" mesh="elbow_u_1_mesh"/>
              <!-- <geom class="collision" pos="0.042681 0.159226 -0.009163" quat="0.996195 0.087156 0 0" mesh="elbow_u_1_mesh"/> -->
                <inertial pos="0.042681 0.1588885 -0.120904" quat="0.704096 -0.0651793 0.0651793 0.704096" mass="0.0372743" diaginertia="4.83011e-05 4.687e-05 6.12888e-06"/>
                <geom class="visual" pos="0.042681 0.169645 -0.068252" quat="0 0 0.996195 0.087156" material="Nylon_12_(with_Formlabs_Fuse_1_3D_Printer)" mesh="arm_v2__1__1_mesh"/>
                <geom class="collision" pos="0.042681 0.169645 -0.068252" quat="0 0 0.996195 0.087156" mesh="arm_v2__1__1_mesh"/>
            </body>
          </body>
        </body>
      </body>
      <body name="shoulder_u__1__1">
        <inertial pos="0.037356 0.0027458000000000066 0.0494" quat="0 0.707107 0 0.707107" mass="0.00757239" diaginertia="2.73e-06 2.6e-06 8.3e-07"/>
        <joint name="right_shoulder_pitch_joint" pos="0.037356 0.010460000000000004 0.0494" axis="0 1 0"/>
        <geom class="visual" pos="0.037356 0.010460000000000004 0.0494" quat="0 0.707107 0 0.707107" material="Generic" mesh="shoulder_u__1__1_mesh"/>
        <!-- <geom class="collision" pos="0.037356 0.010460000000000004 0.0494" quat="0 0.707107 0 0.707107" mesh="shoulder_u__1__1_mesh"/> -->
        <body name="shoulder__1__1">
          <inertial pos="0.02917454 -0.019424200000000003 0.016024" quat="0.704031 0.0655843 0.186859 0.681999" mass="0.129837" diaginertia="9.56099e-05 8.39302e-05 2.49599e-05"/>
          <joint name="right_shoulder_roll_joint" pos="0.037356 -0.013539999999999996 0.0494" axis="1 0 0" range="-0.349066 2.96706"/>
          <geom class="visual" pos="0.037456 -0.013539999999999996 0.0494" quat="0.696364 -0.122788 0.696364 -0.122788" material="PA_12_-_Nylon_-_PA_603-CF_(with_EOS_P_3D_Printers)" mesh="shoulder__1__1_mesh_0"/>
          <geom class="visual" pos="0.037456 -0.013539999999999996 0.0494" quat="0.696364 -0.122788 0.696364 -0.122788" material="Carbon_Fiber_-_Plain" mesh="shoulder__1__1_mesh_1"/>
          <geom class="visual" pos="0.037456 -0.013539999999999996 0.0494" quat="0.696364 -0.122788 0.696364 -0.122788" material="Aluminum_-_Anodized_Glossy_(Grey)" mesh="shoulder__1__1_mesh_2"/>
          <geom class="visual" pos="0.037456 -0.013539999999999996 0.0494" quat="0.696364 -0.122788 0.696364 -0.122788" material="Aluminum_-_Satin" mesh="shoulder__1__1_mesh_3"/>
          <geom class="collision" pos="0.037456 -0.013539999999999996 0.0494" quat="0.696364 -0.122788 0.696364 -0.122788" mesh="shoulder__1__1_mesh_0"/>
          <geom class="collision" pos="0.037456 -0.013539999999999996 0.0494" quat="0.696364 -0.122788 0.696364 -0.122788" mesh="shoulder__1__1_mesh_1"/>
          <geom class="collision" pos="0.037456 -0.013539999999999996 0.0494" quat="0.696364 -0.122788 0.696364 -0.122788" mesh="shoulder__1__1_mesh_2"/>
          <geom class="collision" pos="0.037456 -0.013539999999999996 0.0494" quat="0.696364 -0.122788 0.696364 -0.122788" mesh="shoulder__1__1_mesh_3"/>
          <body name="elbow__1__1">
            <inertial pos="0.0337641 -0.027274800000000002 -0.0387821" quat="0.0436951 0.701884 0.0973557 0.704252" mass="0.0555309" diaginertia="1.58802e-05 1.18149e-05 1.10048e-05"/>
            <joint name="right_elbow_yaw_joint" pos="0.034781 -0.026029999999999998 -0.021432" axis="0 -0.173648 -0.984808" range="-1.5708 1.5708"/>
            <geom class="visual" friction="0.3 0.01 0" pos="0.011959999999999998 0.035232 -0.099606" quat="0.541675 0.454519 0.541675 0.454519" material="Generic" mesh="elbow__1__1_mesh_0"/>
            <geom class="visual" friction="0.3 0.01 0" pos="0.011959999999999998 0.035232 -0.099606" quat="0.541675 0.454519 0.541675 0.454519" material="PA_12_-_Nylon_-_PA_603-CF_(with_EOS_P_3D_Printers)" mesh="elbow__1__1_mesh_1"/>
            <geom class="visual" friction="0.3 0.01 0" pos="0.011959999999999998 0.035232 -0.099606" quat="0.541675 0.454519 0.541675 0.454519" material="Steel_-_Satin" mesh="elbow__1__1_mesh_2"/>
            <geom class="visual" friction="0.3 0.01 0" pos="0.011959999999999998 0.035232 -0.099606" quat="0.541675 0.454519 0.541675 0.454519" material="Aluminum_-_Anodized_Glossy_(Grey)" mesh="elbow__1__1_mesh_3"/>
            <geom class="visual" friction="0.3 0.01 0" pos="0.011959999999999998 0.035232 -0.099606" quat="0.541675 0.454519 0.541675 0.454519" material="Titanium_-_Polished" mesh="elbow__1__1_mesh_4"/>
            <geom class="collision" friction="0.3 0.01 0" pos="0.011959999999999998 0.035232 -0.099606" quat="0.541675 0.454519 0.541675 0.454519" mesh="elbow__1__1_mesh_0"/>
            <geom class="collision" friction="0.3 0.01 0" pos="0.011959999999999998 0.035232 -0.099606" quat="0.541675 0.454519 0.541675 0.454519" mesh="elbow__1__1_mesh_1"/>
            <geom class="collision" friction="0.3 0.01 0" pos="0.011959999999999998 0.035232 -0.099606" quat="0.541675 0.454519 0.541675 0.454519" mesh="elbow__1__1_mesh_2"/>
            <geom class="collision" friction="0.3 0.01 0" pos="0.011959999999999998 0.035232 -0.099606" quat="0.541675 0.454519 0.541675 0.454519" mesh="elbow__1__1_mesh_3"/>
            <geom class="collision" friction="0.3 0.01 0" pos="0.011959999999999998 0.035232 -0.099606" quat="0.541675 0.454519 0.541675 0.454519" mesh="elbow__1__1_mesh_4"/>
            <body name="elbow_u__1__1">
              <!-- <inertial pos="0.042681 -0.031589400000000004 -0.0552667" quat="0.765378 0.643581 0 0" mass="0.00757239" diaginertia="2.73e-06 2.60226e-06 8.27743e-07"/> -->
              <joint name="right_elbow_pitch_joint" pos="0.042681 -0.012020000000000003 -0.042701" axis="0 0.984808 -0.173648" range="-2.61799 0.174533"/>
              <geom class="visual" pos="0.042681 -0.023552000000000003 -0.009684" quat="0.996195 -0.087156 0 0" material="Generic" mesh="elbow_u__1__1_mesh"/>
              <!-- <geom class="collision" pos="0.042681 -0.023552000000000003 -0.009684" quat="0.996195 -0.087156 0 0" mesh="elbow_u__1__1_mesh"/> -->
                <inertial pos="0.042681 -0.0232141 -0.121425" quat="0.704096 0.0651793 -0.0651793 0.704096" mass="0.0372743" diaginertia="4.83011e-05 4.687e-05 6.12888e-06"/>
                <geom class="visual" pos="0.042681 -0.033971 -0.068773" quat="0.087156 0.996195 0 0" material="Nylon_12_(with_Formlabs_Fuse_1_3D_Printer)" mesh="arm_v2_1_mesh"/>
                <geom class="collision" pos="0.042681 -0.028971 -0.068773" quat="0.087156 0.996195 0 0" mesh="arm_v2_1_mesh"/>
                <geom class="collision" pos="0.042681 -0.003971 -0.1552" quat="0.707107 0 0 0" type="box" size="0.02 0.02 0.02"/>
                <geom class="collision" pos="0.06081 0.015971 -0.1552" quat="0.707107 0 0 0" type="box" size="0.002 0.01 0.02" rgba="1 0 0 1"/>
                <geom class="collision" pos="0.02481 0.015971 -0.1552" quat="0.707107 0 0 0" type="box" size="0.002 0.01 0.02" rgba="1 0 0 1"/>
                <geom class="collision" pos="0.04281 0.015971 -0.1372" quat="0.707107 0 0 0" type="box" size="0.02 0.01 0.002" rgba="1 0 0 1"/>
                <geom class="collision" pos="0.04281 0.015971 -0.1732" quat="0.707107 0 0 0" type="box" size="0.02 0.01 0.002" rgba="1 0 0 1"/>
            </body>
          </body>
        </body>
      </body>
    </body>
  </worldbody>
  <actuator>
    <position name="left_ankle_roll" joint="left_ankle_roll_joint" forcerange="-3.5 3.5"  kp="10" />
    <position name="left_ankle_pitch" joint="left_ankle_pitch_joint" forcerange="-3.5 3.5"  kp="10" />
    <position name="left_bottom_knee" joint="left_bottom_knee_joint" forcerange="-3.5 3.5"  kp="10" />
    <position name="left_upper_knee" joint="left_upper_knee_joint" forcerange="-3.5 3.5"  kp="10" />
    <position name="left_hip_pitch" joint="left_hip_pitch_joint" forcerange="-3.5 3.5"  kp="10" />
    <position name="left_hip_roll" joint="left_hip_roll_joint" forcerange="-3.5 3.5"  kp="10" />
    <position name="left_hip_yaw" joint="left_hip_yaw_joint" forcerange="-3.5 3.5"  kp="10" />
    <position name="right_ankle_roll" joint="right_ankle_roll_joint" forcerange="-3.5 3.5"  kp="10" />
    <position name="right_ankle_pitch" joint="right_ankle_pitch_joint" forcerange="-3.5 3.5"  kp="10" />
    <position name="right_bottom_knee" joint="right_bottom_knee_joint" forcerange="-3.5 3.5"  kp="10" />
    <position name="right_upper_knee" joint="right_upper_knee_joint" forcerange="-3.5 3.5"  kp="10" />
    <position name="right_hip_pitch" joint="right_hip_pitch_joint" forcerange="-3.5 3.5"  kp="10" />
    <position name="right_hip_roll" joint="right_hip_roll_joint" forcerange="-3.5 3.5"  kp="10" />
    <position name="right_hip_yaw" joint="right_hip_yaw_joint" forcerange="-3.5 3.5"  kp="10" />
    <position name="waist_yaw" joint="waist_yaw_joint" forcerange="-3.5 3.5"  kp="10" />
    <position name="head_pitch" joint="head_pitch_joint" forcerange="-3.5 3.5"  kp="10" />
    <position name="head_yaw" joint="head_yaw_joint" forcerange="-3.5 3.5"  kp="10" />
    <position name="left_elbow_pitch" joint="left_elbow_pitch_joint" forcerange="-3.5 3.5"  kp="10" />
    <position name="left_elbow_yaw" joint="left_elbow_yaw_joint" forcerange="-3.5 3.5"  kp="10" />
    <position name="left_shoulder_roll" joint="left_shoulder_roll_joint" forcerange="-3.5 3.5"  kp="10" />
    <position name="left_shoulder_pitch" joint="left_shoulder_pitch_joint" forcerange="-3.5 3.5"  kp="10" />
    <position name="right_elbow_pitch" joint="right_elbow_pitch_joint" forcerange="-3.5 3.5"  kp="10" />
    <position name="right_elbow_yaw" joint="right_elbow_yaw_joint" forcerange="-3.5 3.5"  kp="10" />
    <position name="right_shoulder_roll" joint="right_shoulder_roll_joint" forcerange="-3.5 3.5"  kp="10" />
    <position name="right_shoulder_pitch" joint="right_shoulder_pitch_joint" forcerange="-3.5 3.5"  kp="10" />
  </actuator>
  <sensor>
     <jointpos name="left_ankle_roll_pos" joint="left_ankle_roll_joint"  />
    <jointpos name="left_ankle_pitch_pos" joint="left_ankle_pitch_joint"  />
    <jointpos name="left_bottom_knee_pos" joint="left_bottom_knee_joint"  />
    <jointpos name="left_upper_knee_pos" joint="left_upper_knee_joint"  />
    <jointpos name="left_hip_pitch_pos" joint="left_hip_pitch_joint"  />
    <jointpos name="left_hip_roll_pos" joint="left_hip_roll_joint"  />
    <jointpos name="left_hip_yaw_pos" joint="left_hip_yaw_joint"  />
    <jointpos name="right_ankle_roll_pos" joint="right_ankle_roll_joint"  />
    <jointpos name="right_ankle_pitch_pos" joint="right_ankle_pitch_joint"  />
    <jointpos name="right_bottom_knee_pos" joint="right_bottom_knee_joint"  />
    <jointpos name="right_upper_knee_pos" joint="right_upper_knee_joint"  />
    <jointpos name="right_hip_pitch_pos" joint="right_hip_pitch_joint"  />
    <jointpos name="right_hip_roll_pos" joint="right_hip_roll_joint"  />
    <jointpos name="right_hip_yaw_pos" joint="right_hip_yaw_joint"  />
    <jointpos name="waist_yaw_pos" joint="waist_yaw_joint"  />
    <jointpos name="head_pitch_pos" joint="head_pitch_joint"  />
    <jointpos name="head_yaw_pos" joint="head_yaw_joint"  />
    <jointpos name="left_elbow_pitch_pos" joint="left_elbow_pitch_joint"  />
    <jointpos name="left_elbow_yaw_pos" joint="left_elbow_yaw_joint"  />
    <jointpos name="left_shoulder_roll_pos" joint="left_shoulder_roll_joint"  />
    <jointpos name="left_shoulder_pitch_pos" joint="left_shoulder_pitch_joint"  />
    <jointpos name="right_elbow_pitch_pos" joint="right_elbow_pitch_joint"  />
    <jointpos name="right_elbow_yaw_pos" joint="right_elbow_yaw_joint"  />
    <jointpos name="right_shoulder_roll_pos" joint="right_shoulder_roll_joint"  />
    <jointpos name="right_shoulder_pitch_pos" joint="right_shoulder_pitch_joint"  />
  </sensor>
</mujoco>
